<?xml version="1.0" encoding="UTF-8"?>
<!-- Generated by org.testng.reporters.JUnitReportReporter -->
<testsuite hostname="LAPTOP-GAD15EJN" name="yjp.VirtualOrder" tests="8" failures="5" timestamp="9 Dec 2019 11:43:38 GMT" time="72.047" errors="1">
  <testcase name="Enquiry_OrderByName" time="7.943" classname="yjp.VirtualOrder"/>
  <testcase name="OrderDetail" time="11.646" classname="yjp.VirtualOrder">
    <failure type="java.lang.AssertionError" message="expected [true] but found [false]">
      <![CDATA[java.lang.AssertionError: expected [true] but found [false]
	at org.testng.Assert.fail(Assert.java:94)
	at org.testng.Assert.failNotEquals(Assert.java:513)
	at org.testng.Assert.assertTrue(Assert.java:42)
	at org.testng.Assert.assertTrue(Assert.java:52)
	at yjp.VirtualOrder.OrderDetail(VirtualOrder.java:80)
	at sun.reflect.NativeMethodAccessorImpl.invoke0(Native Method)
	at sun.reflect.NativeMethodAccessorImpl.invoke(Unknown Source)
	at sun.reflect.DelegatingMethodAccessorImpl.invoke(Unknown Source)
	at java.lang.reflect.Method.invoke(Unknown Source)
	at org.testng.internal.MethodInvocationHelper.invokeMethod(MethodInvocationHelper.java:86)
	at org.testng.internal.Invoker.invokeMethod(Invoker.java:645)
	at org.testng.internal.Invoker.invokeTestMethod(Invoker.java:822)
	at org.testng.internal.Invoker.invokeTestMethods(Invoker.java:1130)
	at org.testng.internal.TestMethodWorker.invokeTestMethods(TestMethodWorker.java:129)
	at org.testng.internal.TestMethodWorker.run(TestMethodWorker.java:112)
	at org.testng.TestRunner.privateRun(TestRunner.java:782)
	at org.testng.TestRunner.run(TestRunner.java:632)
	at org.testng.SuiteRunner.runTest(SuiteRunner.java:366)
	at org.testng.SuiteRunner.runSequentially(SuiteRunner.java:361)
	at org.testng.SuiteRunner.privateRun(SuiteRunner.java:319)
	at org.testng.SuiteRunner.run(SuiteRunner.java:268)
	at org.testng.SuiteRunnerWorker.runSuite(SuiteRunnerWorker.java:52)
	at org.testng.SuiteRunnerWorker.run(SuiteRunnerWorker.java:86)
	at org.testng.TestNG.runSuitesSequentially(TestNG.java:1244)
	at org.testng.TestNG.runSuitesLocally(TestNG.java:1169)
	at org.testng.TestNG.run(TestNG.java:1064)
	at org.testng.remote.RemoteTestNG.run(RemoteTestNG.java:113)
	at org.testng.remote.RemoteTestNG.initAndRun(RemoteTestNG.java:206)
	at org.testng.remote.RemoteTestNG.main(RemoteTestNG.java:177)
]]>
    </failure>
  </testcase> <!-- OrderDetail -->
  <testcase name="selectOrder" time="13.332" classname="yjp.VirtualOrder">
    <failure type="java.lang.AssertionError" message="expected [true] but found [false]">
      <![CDATA[java.lang.AssertionError: expected [true] but found [false]
	at org.testng.Assert.fail(Assert.java:94)
	at org.testng.Assert.failNotEquals(Assert.java:513)
	at org.testng.Assert.assertTrue(Assert.java:42)
	at org.testng.Assert.assertTrue(Assert.java:52)
	at yjp.VirtualOrder.selectOrder(VirtualOrder.java:41)
	at sun.reflect.NativeMethodAccessorImpl.invoke0(Native Method)
	at sun.reflect.NativeMethodAccessorImpl.invoke(Unknown Source)
	at sun.reflect.DelegatingMethodAccessorImpl.invoke(Unknown Source)
	at java.lang.reflect.Method.invoke(Unknown Source)
	at org.testng.internal.MethodInvocationHelper.invokeMethod(MethodInvocationHelper.java:86)
	at org.testng.internal.Invoker.invokeMethod(Invoker.java:645)
	at org.testng.internal.Invoker.invokeTestMethod(Invoker.java:822)
	at org.testng.internal.Invoker.invokeTestMethods(Invoker.java:1130)
	at org.testng.internal.TestMethodWorker.invokeTestMethods(TestMethodWorker.java:129)
	at org.testng.internal.TestMethodWorker.run(TestMethodWorker.java:112)
	at org.testng.TestRunner.privateRun(TestRunner.java:782)
	at org.testng.TestRunner.run(TestRunner.java:632)
	at org.testng.SuiteRunner.runTest(SuiteRunner.java:366)
	at org.testng.SuiteRunner.runSequentially(SuiteRunner.java:361)
	at org.testng.SuiteRunner.privateRun(SuiteRunner.java:319)
	at org.testng.SuiteRunner.run(SuiteRunner.java:268)
	at org.testng.SuiteRunnerWorker.runSuite(SuiteRunnerWorker.java:52)
	at org.testng.SuiteRunnerWorker.run(SuiteRunnerWorker.java:86)
	at org.testng.TestNG.runSuitesSequentially(TestNG.java:1244)
	at org.testng.TestNG.runSuitesLocally(TestNG.java:1169)
	at org.testng.TestNG.run(TestNG.java:1064)
	at org.testng.remote.RemoteTestNG.run(RemoteTestNG.java:113)
	at org.testng.remote.RemoteTestNG.initAndRun(RemoteTestNG.java:206)
	at org.testng.remote.RemoteTestNG.main(RemoteTestNG.java:177)
]]>
    </failure>
  </testcase> <!-- selectOrder -->
  <testcase name="cancelOrder" time="3.911" classname="yjp.VirtualOrder">
    <failure type="java.lang.AssertionError" message="expected [true] but found [false]">
      <![CDATA[java.lang.AssertionError: expected [true] but found [false]
	at org.testng.Assert.fail(Assert.java:94)
	at org.testng.Assert.failNotEquals(Assert.java:513)
	at org.testng.Assert.assertTrue(Assert.java:42)
	at org.testng.Assert.assertTrue(Assert.java:52)
	at yjp.VirtualOrder.cancelOrder(VirtualOrder.java:96)
	at sun.reflect.NativeMethodAccessorImpl.invoke0(Native Method)
	at sun.reflect.NativeMethodAccessorImpl.invoke(Unknown Source)
	at sun.reflect.DelegatingMethodAccessorImpl.invoke(Unknown Source)
	at java.lang.reflect.Method.invoke(Unknown Source)
	at org.testng.internal.MethodInvocationHelper.invokeMethod(MethodInvocationHelper.java:86)
	at org.testng.internal.Invoker.invokeMethod(Invoker.java:645)
	at org.testng.internal.Invoker.invokeTestMethod(Invoker.java:822)
	at org.testng.internal.Invoker.invokeTestMethods(Invoker.java:1130)
	at org.testng.internal.TestMethodWorker.invokeTestMethods(TestMethodWorker.java:129)
	at org.testng.internal.TestMethodWorker.run(TestMethodWorker.java:112)
	at org.testng.TestRunner.privateRun(TestRunner.java:782)
	at org.testng.TestRunner.run(TestRunner.java:632)
	at org.testng.SuiteRunner.runTest(SuiteRunner.java:366)
	at org.testng.SuiteRunner.runSequentially(SuiteRunner.java:361)
	at org.testng.SuiteRunner.privateRun(SuiteRunner.java:319)
	at org.testng.SuiteRunner.run(SuiteRunner.java:268)
	at org.testng.SuiteRunnerWorker.runSuite(SuiteRunnerWorker.java:52)
	at org.testng.SuiteRunnerWorker.run(SuiteRunnerWorker.java:86)
	at org.testng.TestNG.runSuitesSequentially(TestNG.java:1244)
	at org.testng.TestNG.runSuitesLocally(TestNG.java:1169)
	at org.testng.TestNG.run(TestNG.java:1064)
	at org.testng.remote.RemoteTestNG.run(RemoteTestNG.java:113)
	at org.testng.remote.RemoteTestNG.initAndRun(RemoteTestNG.java:206)
	at org.testng.remote.RemoteTestNG.main(RemoteTestNG.java:177)
]]>
    </failure>
  </testcase> <!-- cancelOrder -->
  <testcase name="Enquiry_OrderByID" time="7.284" classname="yjp.VirtualOrder"/>
  <testcase name="assessOrder_Fail1" time="19.370" classname="yjp.VirtualOrder">
    <failure type="java.lang.AssertionError" message="expected [true] but found [false]">
      <![CDATA[java.lang.AssertionError: expected [true] but found [false]
	at org.testng.Assert.fail(Assert.java:94)
	at org.testng.Assert.failNotEquals(Assert.java:513)
	at org.testng.Assert.assertTrue(Assert.java:42)
	at org.testng.Assert.assertTrue(Assert.java:52)
	at yjp.VirtualOrder.assessOrder_Fail1(VirtualOrder.java:56)
	at sun.reflect.NativeMethodAccessorImpl.invoke0(Native Method)
	at sun.reflect.NativeMethodAccessorImpl.invoke(Unknown Source)
	at sun.reflect.DelegatingMethodAccessorImpl.invoke(Unknown Source)
	at java.lang.reflect.Method.invoke(Unknown Source)
	at org.testng.internal.MethodInvocationHelper.invokeMethod(MethodInvocationHelper.java:86)
	at org.testng.internal.Invoker.invokeMethod(Invoker.java:645)
	at org.testng.internal.Invoker.invokeTestMethod(Invoker.java:822)
	at org.testng.internal.Invoker.invokeTestMethods(Invoker.java:1130)
	at org.testng.internal.TestMethodWorker.invokeTestMethods(TestMethodWorker.java:129)
	at org.testng.internal.TestMethodWorker.run(TestMethodWorker.java:112)
	at org.testng.TestRunner.privateRun(TestRunner.java:782)
	at org.testng.TestRunner.run(TestRunner.java:632)
	at org.testng.SuiteRunner.runTest(SuiteRunner.java:366)
	at org.testng.SuiteRunner.runSequentially(SuiteRunner.java:361)
	at org.testng.SuiteRunner.privateRun(SuiteRunner.java:319)
	at org.testng.SuiteRunner.run(SuiteRunner.java:268)
	at org.testng.SuiteRunnerWorker.runSuite(SuiteRunnerWorker.java:52)
	at org.testng.SuiteRunnerWorker.run(SuiteRunnerWorker.java:86)
	at org.testng.TestNG.runSuitesSequentially(TestNG.java:1244)
	at org.testng.TestNG.runSuitesLocally(TestNG.java:1169)
	at org.testng.TestNG.run(TestNG.java:1064)
	at org.testng.remote.RemoteTestNG.run(RemoteTestNG.java:113)
	at org.testng.remote.RemoteTestNG.initAndRun(RemoteTestNG.java:206)
	at org.testng.remote.RemoteTestNG.main(RemoteTestNG.java:177)
]]>
    </failure>
  </testcase> <!-- assessOrder_Fail1 -->
  <testcase name="Enquiry_Fail" time="7.886" classname="yjp.VirtualOrder">
    <failure type="java.lang.AssertionError" message="expected [true] but found [false]">
      <![CDATA[java.lang.AssertionError: expected [true] but found [false]
	at org.testng.Assert.fail(Assert.java:94)
	at org.testng.Assert.failNotEquals(Assert.java:513)
	at org.testng.Assert.assertTrue(Assert.java:42)
	at org.testng.Assert.assertTrue(Assert.java:52)
	at yjp.VirtualOrder.Enquiry_Fail(VirtualOrder.java:121)
	at sun.reflect.NativeMethodAccessorImpl.invoke0(Native Method)
	at sun.reflect.NativeMethodAccessorImpl.invoke(Unknown Source)
	at sun.reflect.DelegatingMethodAccessorImpl.invoke(Unknown Source)
	at java.lang.reflect.Method.invoke(Unknown Source)
	at org.testng.internal.MethodInvocationHelper.invokeMethod(MethodInvocationHelper.java:86)
	at org.testng.internal.Invoker.invokeMethod(Invoker.java:645)
	at org.testng.internal.Invoker.invokeTestMethod(Invoker.java:822)
	at org.testng.internal.Invoker.invokeTestMethods(Invoker.java:1130)
	at org.testng.internal.TestMethodWorker.invokeTestMethods(TestMethodWorker.java:129)
	at org.testng.internal.TestMethodWorker.run(TestMethodWorker.java:112)
	at org.testng.TestRunner.privateRun(TestRunner.java:782)
	at org.testng.TestRunner.run(TestRunner.java:632)
	at org.testng.SuiteRunner.runTest(SuiteRunner.java:366)
	at org.testng.SuiteRunner.runSequentially(SuiteRunner.java:361)
	at org.testng.SuiteRunner.privateRun(SuiteRunner.java:319)
	at org.testng.SuiteRunner.run(SuiteRunner.java:268)
	at org.testng.SuiteRunnerWorker.runSuite(SuiteRunnerWorker.java:52)
	at org.testng.SuiteRunnerWorker.run(SuiteRunnerWorker.java:86)
	at org.testng.TestNG.runSuitesSequentially(TestNG.java:1244)
	at org.testng.TestNG.runSuitesLocally(TestNG.java:1169)
	at org.testng.TestNG.run(TestNG.java:1064)
	at org.testng.remote.RemoteTestNG.run(RemoteTestNG.java:113)
	at org.testng.remote.RemoteTestNG.initAndRun(RemoteTestNG.java:206)
	at org.testng.remote.RemoteTestNG.main(RemoteTestNG.java:177)
]]>
    </failure>
  </testcase> <!-- Enquiry_Fail -->
  <testcase name="assessOrder_Fail2" time="0.675" classname="yjp.VirtualOrder">
    <error type="org.openqa.selenium.ElementClickInterceptedException" message="Element &lt;img src=&quot;/public/images/star-off.png&quot;&gt; is not clickable at point (708,194) because another element &lt;div id=&quot;layui-layer-shade1&quot; class=&quot;layui-layer-shade&quot;&gt; obscures it
Build info: version: &#039;3.141.59&#039;, revision: &#039;e82be7d358&#039;, time: &#039;2018-11-14T08:25:53&#039;
System info: host: &#039;LAPTOP-GAD15EJN&#039;, ip: &#039;169.254.0.95&#039;, os.name: &#039;Windows 10&#039;, os.arch: &#039;amd64&#039;, os.version: &#039;10.0&#039;, java.version: &#039;1.8.0_73&#039;
Driver info: org.openqa.selenium.firefox.FirefoxDriver
Capabilities {acceptInsecureCerts: true, browserName: firefox, browserVersion: 69.0.3, javascriptEnabled: true, moz:accessibilityChecks: false, moz:buildID: 20191009172106, moz:geckodriverVersion: 0.24.0, moz:headless: false, moz:processID: 3688, moz:profile: E:\Temp\rust_mozprofile.MNk..., moz:shutdownTimeout: 60000, moz:useNonSpecCompliantPointerOrigin: false, moz:webdriverClick: true, pageLoadStrategy: normal, platform: WINDOWS, platformName: WINDOWS, platformVersion: 10.0, rotatable: false, setWindowRect: true, strictFileInteractability: false, timeouts: {implicit: 0, pageLoad: 300000, script: 30000}, unhandledPromptBehavior: dismiss and notify}
Session ID: 6d85dfd1-c81e-47d9-ae12-f363293d0e3f">
      <![CDATA[org.openqa.selenium.ElementClickInterceptedException: Element <img src="/public/images/star-off.png"> is not clickable at point (708,194) because another element <div id="layui-layer-shade1" class="layui-layer-shade"> obscures it
Build info: version: '3.141.59', revision: 'e82be7d358', time: '2018-11-14T08:25:53'
System info: host: 'LAPTOP-GAD15EJN', ip: '169.254.0.95', os.name: 'Windows 10', os.arch: 'amd64', os.version: '10.0', java.version: '1.8.0_73'
Driver info: org.openqa.selenium.firefox.FirefoxDriver
Capabilities {acceptInsecureCerts: true, browserName: firefox, browserVersion: 69.0.3, javascriptEnabled: true, moz:accessibilityChecks: false, moz:buildID: 20191009172106, moz:geckodriverVersion: 0.24.0, moz:headless: false, moz:processID: 3688, moz:profile: E:\Temp\rust_mozprofile.MNk..., moz:shutdownTimeout: 60000, moz:useNonSpecCompliantPointerOrigin: false, moz:webdriverClick: true, pageLoadStrategy: normal, platform: WINDOWS, platformName: WINDOWS, platformVersion: 10.0, rotatable: false, setWindowRect: true, strictFileInteractability: false, timeouts: {implicit: 0, pageLoad: 300000, script: 30000}, unhandledPromptBehavior: dismiss and notify}
Session ID: 6d85dfd1-c81e-47d9-ae12-f363293d0e3f
	at sun.reflect.NativeConstructorAccessorImpl.newInstance0(Native Method)
	at sun.reflect.NativeConstructorAccessorImpl.newInstance(Unknown Source)
	at sun.reflect.DelegatingConstructorAccessorImpl.newInstance(Unknown Source)
	at java.lang.reflect.Constructor.newInstance(Unknown Source)
	at org.openqa.selenium.remote.http.W3CHttpResponseCodec.createException(W3CHttpResponseCodec.java:187)
	at org.openqa.selenium.remote.http.W3CHttpResponseCodec.decode(W3CHttpResponseCodec.java:122)
	at org.openqa.selenium.remote.http.W3CHttpResponseCodec.decode(W3CHttpResponseCodec.java:49)
	at org.openqa.selenium.remote.HttpCommandExecutor.execute(HttpCommandExecutor.java:158)
	at org.openqa.selenium.remote.service.DriverCommandExecutor.execute(DriverCommandExecutor.java:83)
	at org.openqa.selenium.remote.RemoteWebDriver.execute(RemoteWebDriver.java:552)
	at org.openqa.selenium.remote.RemoteWebElement.execute(RemoteWebElement.java:285)
	at org.openqa.selenium.remote.RemoteWebElement.click(RemoteWebElement.java:84)
	at com.webtest.core.WebDriverEngine.click(WebDriverEngine.java:154)
	at yjp.VirtualOrder.assessOrder_Fail2(VirtualOrder.java:66)
	at sun.reflect.NativeMethodAccessorImpl.invoke0(Native Method)
	at sun.reflect.NativeMethodAccessorImpl.invoke(Unknown Source)
	at sun.reflect.DelegatingMethodAccessorImpl.invoke(Unknown Source)
	at java.lang.reflect.Method.invoke(Unknown Source)
	at org.testng.internal.MethodInvocationHelper.invokeMethod(MethodInvocationHelper.java:86)
	at org.testng.internal.Invoker.invokeMethod(Invoker.java:645)
	at org.testng.internal.Invoker.invokeTestMethod(Invoker.java:822)
	at org.testng.internal.Invoker.invokeTestMethods(Invoker.java:1130)
	at org.testng.internal.TestMethodWorker.invokeTestMethods(TestMethodWorker.java:129)
	at org.testng.internal.TestMethodWorker.run(TestMethodWorker.java:112)
	at org.testng.TestRunner.privateRun(TestRunner.java:782)
	at org.testng.TestRunner.run(TestRunner.java:632)
	at org.testng.SuiteRunner.runTest(SuiteRunner.java:366)
	at org.testng.SuiteRunner.runSequentially(SuiteRunner.java:361)
	at org.testng.SuiteRunner.privateRun(SuiteRunner.java:319)
	at org.testng.SuiteRunner.run(SuiteRunner.java:268)
	at org.testng.SuiteRunnerWorker.runSuite(SuiteRunnerWorker.java:52)
	at org.testng.SuiteRunnerWorker.run(SuiteRunnerWorker.java:86)
	at org.testng.TestNG.runSuitesSequentially(TestNG.java:1244)
	at org.testng.TestNG.runSuitesLocally(TestNG.java:1169)
	at org.testng.TestNG.run(TestNG.java:1064)
	at org.testng.remote.RemoteTestNG.run(RemoteTestNG.java:113)
	at org.testng.remote.RemoteTestNG.initAndRun(RemoteTestNG.java:206)
	at org.testng.remote.RemoteTestNG.main(RemoteTestNG.java:177)
]]>
    </error>
  </testcase> <!-- assessOrder_Fail2 -->
</testsuite> <!-- yjp.VirtualOrder -->
